[2024-03-25T16:10:46.412+0000] {taskinstance.py:1979} INFO - Dependencies all met for dep_context=non-requeueable deps ti=<TaskInstance: retail_dag.send_retail_to_dataset manual__2024-03-25T16:09:30.717735+00:00 [queued]>
[2024-03-25T16:10:46.435+0000] {taskinstance.py:1979} INFO - Dependencies all met for dep_context=requeueable deps ti=<TaskInstance: retail_dag.send_retail_to_dataset manual__2024-03-25T16:09:30.717735+00:00 [queued]>
[2024-03-25T16:10:46.436+0000] {taskinstance.py:2193} INFO - Starting attempt 1 of 1
[2024-03-25T16:10:46.464+0000] {taskinstance.py:2217} INFO - Executing <Task(GCSToBigQueryOperator): send_retail_to_dataset> on 2024-03-25 16:09:30.717735+00:00
[2024-03-25T16:10:46.476+0000] {standard_task_runner.py:60} INFO - Started process 1104 to run task
[2024-03-25T16:10:46.483+0000] {standard_task_runner.py:87} INFO - Running: ['***', 'tasks', 'run', 'retail_dag', 'send_retail_to_dataset', 'manual__2024-03-25T16:09:30.717735+00:00', '--job-id', '23', '--raw', '--subdir', 'DAGS_FOLDER/retail.py', '--cfg-path', '/tmp/tmp839o82r6']
[2024-03-25T16:10:46.486+0000] {standard_task_runner.py:88} INFO - Job 23: Subtask send_retail_to_dataset
[2024-03-25T16:10:46.582+0000] {task_command.py:423} INFO - Running <TaskInstance: retail_dag.send_retail_to_dataset manual__2024-03-25T16:09:30.717735+00:00 [running]> on host b77f7ef9c21f
[2024-03-25T16:10:46.783+0000] {taskinstance.py:2513} INFO - Exporting env vars: AIRFLOW_CTX_DAG_OWNER='***' AIRFLOW_CTX_DAG_ID='retail_dag' AIRFLOW_CTX_TASK_ID='send_retail_to_dataset' AIRFLOW_CTX_EXECUTION_DATE='2024-03-25T16:09:30.717735+00:00' AIRFLOW_CTX_TRY_NUMBER='1' AIRFLOW_CTX_DAG_RUN_ID='manual__2024-03-25T16:09:30.717735+00:00'
[2024-03-25T16:10:46.825+0000] {taskinstance.py:2731} ERROR - Task failed with exception
Traceback (most recent call last):
  File "/home/airflow/.local/lib/python3.8/site-packages/airflow/models/taskinstance.py", line 444, in _execute_task
    result = _execute_callable(context=context, **execute_callable_kwargs)
  File "/home/airflow/.local/lib/python3.8/site-packages/airflow/models/taskinstance.py", line 414, in _execute_callable
    return execute_callable(context=context, **execute_callable_kwargs)
  File "/home/airflow/.local/lib/python3.8/site-packages/airflow/providers/google/cloud/transfers/gcs_to_bigquery.py", line 322, in execute
    hook = BigQueryHook(
  File "/home/airflow/.local/lib/python3.8/site-packages/airflow/providers/google/cloud/hooks/bigquery.py", line 118, in __init__
    super().__init__(
  File "/home/airflow/.local/lib/python3.8/site-packages/airflow/providers/google/common/hooks/base_google.py", line 251, in __init__
    self.extras: dict = self.get_connection(self.gcp_conn_id).extra_dejson
  File "/home/airflow/.local/lib/python3.8/site-packages/airflow/hooks/base.py", line 82, in get_connection
    conn = Connection.get_connection_from_secrets(conn_id)
  File "/home/airflow/.local/lib/python3.8/site-packages/airflow/models/connection.py", line 514, in get_connection_from_secrets
    raise AirflowNotFoundException(f"The conn_id `{conn_id}` isn't defined")
airflow.exceptions.AirflowNotFoundException: The conn_id `google_cloud_default` isn't defined
[2024-03-25T16:10:46.842+0000] {taskinstance.py:1149} INFO - Marking task as FAILED. dag_id=retail_dag, task_id=send_retail_to_dataset, execution_date=20240325T160930, start_date=20240325T161046, end_date=20240325T161046
[2024-03-25T16:10:46.870+0000] {standard_task_runner.py:107} ERROR - Failed to execute job 23 for task send_retail_to_dataset (The conn_id `google_cloud_default` isn't defined; 1104)
[2024-03-25T16:10:46.895+0000] {local_task_job_runner.py:234} INFO - Task exited with return code 1
[2024-03-25T16:10:46.930+0000] {taskinstance.py:3312} INFO - 0 downstream tasks scheduled from follow-on schedule check
