[2024-04-20T21:13:35.627+0000] {taskinstance.py:1979} INFO - Dependencies all met for dep_context=non-requeueable deps ti=<TaskInstance: dbt_dag_gcp.dbt_run manual__2024-04-20T21:13:28.054676+00:00 [queued]>
[2024-04-20T21:13:35.652+0000] {taskinstance.py:1979} INFO - Dependencies all met for dep_context=requeueable deps ti=<TaskInstance: dbt_dag_gcp.dbt_run manual__2024-04-20T21:13:28.054676+00:00 [queued]>
[2024-04-20T21:13:35.653+0000] {taskinstance.py:2193} INFO - Starting attempt 1 of 1
[2024-04-20T21:13:35.687+0000] {taskinstance.py:2217} INFO - Executing <Task(BashOperator): dbt_run> on 2024-04-20 21:13:28.054676+00:00
[2024-04-20T21:13:35.699+0000] {standard_task_runner.py:60} INFO - Started process 188 to run task
[2024-04-20T21:13:35.708+0000] {standard_task_runner.py:87} INFO - Running: ['***', 'tasks', 'run', 'dbt_dag_gcp', 'dbt_run', 'manual__2024-04-20T21:13:28.054676+00:00', '--job-id', '240', '--raw', '--subdir', 'DAGS_FOLDER/dbt_dag.py', '--cfg-path', '/tmp/tmprk96lqi6']
[2024-04-20T21:13:35.711+0000] {standard_task_runner.py:88} INFO - Job 240: Subtask dbt_run
[2024-04-20T21:13:35.804+0000] {task_command.py:423} INFO - Running <TaskInstance: dbt_dag_gcp.dbt_run manual__2024-04-20T21:13:28.054676+00:00 [running]> on host cead0b1f6896
[2024-04-20T21:13:36.000+0000] {taskinstance.py:2513} INFO - Exporting env vars: AIRFLOW_CTX_DAG_OWNER='***' AIRFLOW_CTX_DAG_ID='dbt_dag_gcp' AIRFLOW_CTX_TASK_ID='dbt_run' AIRFLOW_CTX_EXECUTION_DATE='2024-04-20T21:13:28.054676+00:00' AIRFLOW_CTX_TRY_NUMBER='1' AIRFLOW_CTX_DAG_RUN_ID='manual__2024-04-20T21:13:28.054676+00:00'
[2024-04-20T21:13:36.004+0000] {subprocess.py:63} INFO - Tmp dir root location: /tmp
[2024-04-20T21:13:36.007+0000] {subprocess.py:75} INFO - Running command: ['/usr/bin/bash', '-c', 'cd /opt/***/dags/dbt/***_dbt_gcp && dbt run --profiles-dir .']
[2024-04-20T21:13:36.032+0000] {subprocess.py:86} INFO - Output:
[2024-04-20T21:13:45.857+0000] {subprocess.py:93} INFO - [0m21:13:45  Running with dbt=1.7.10
[2024-04-20T21:13:52.593+0000] {subprocess.py:93} INFO - [0m21:13:52  Registered adapter: bigquery=1.7.6
[2024-04-20T21:13:52.669+0000] {subprocess.py:93} INFO - [0m21:13:52  Unable to do partial parsing because profile has changed
[2024-04-20T21:13:57.768+0000] {subprocess.py:93} INFO - [0m21:13:57  Found 5 models, 10 tests, 1 source, 0 exposures, 0 metrics, 454 macros, 0 groups, 0 semantic models
[2024-04-20T21:13:57.776+0000] {subprocess.py:93} INFO - [0m21:13:57
[2024-04-20T21:13:57.813+0000] {subprocess.py:93} INFO - [0m21:13:57
[2024-04-20T21:13:57.814+0000] {subprocess.py:93} INFO - [0m21:13:57  Finished running  in 0 hours 0 minutes and 0.04 seconds (0.04s).
[2024-04-20T21:13:57.816+0000] {subprocess.py:93} INFO - [0m21:13:57  Encountered an error:
[2024-04-20T21:13:57.817+0000] {subprocess.py:93} INFO - Database Error
[2024-04-20T21:13:57.818+0000] {subprocess.py:93} INFO -   [Errno 2] No such file or directory: '/***-project/include/gcp/service_account.json'
[2024-04-20T21:14:00.109+0000] {subprocess.py:97} INFO - Command exited with return code 2
[2024-04-20T21:14:00.134+0000] {taskinstance.py:2731} ERROR - Task failed with exception
Traceback (most recent call last):
  File "/home/airflow/.local/lib/python3.8/site-packages/airflow/models/taskinstance.py", line 444, in _execute_task
    result = _execute_callable(context=context, **execute_callable_kwargs)
  File "/home/airflow/.local/lib/python3.8/site-packages/airflow/models/taskinstance.py", line 414, in _execute_callable
    return execute_callable(context=context, **execute_callable_kwargs)
  File "/home/airflow/.local/lib/python3.8/site-packages/airflow/operators/bash.py", line 212, in execute
    raise AirflowException(
airflow.exceptions.AirflowException: Bash command failed. The command returned a non-zero exit code 2.
[2024-04-20T21:14:00.140+0000] {taskinstance.py:1149} INFO - Marking task as FAILED. dag_id=dbt_dag_gcp, task_id=dbt_run, execution_date=20240420T211328, start_date=20240420T211335, end_date=20240420T211400
[2024-04-20T21:14:00.171+0000] {standard_task_runner.py:107} ERROR - Failed to execute job 240 for task dbt_run (Bash command failed. The command returned a non-zero exit code 2.; 188)
[2024-04-20T21:14:00.198+0000] {local_task_job_runner.py:234} INFO - Task exited with return code 1
[2024-04-20T21:14:00.245+0000] {taskinstance.py:3312} INFO - 0 downstream tasks scheduled from follow-on schedule check
