[2024-03-25T16:26:56.692+0000] {taskinstance.py:1979} INFO - Dependencies all met for dep_context=non-requeueable deps ti=<TaskInstance: retail_dag.send_retail_to_dataset manual__2024-03-25T16:26:06.898165+00:00 [queued]>
[2024-03-25T16:26:56.710+0000] {taskinstance.py:1979} INFO - Dependencies all met for dep_context=requeueable deps ti=<TaskInstance: retail_dag.send_retail_to_dataset manual__2024-03-25T16:26:06.898165+00:00 [queued]>
[2024-03-25T16:26:56.711+0000] {taskinstance.py:2193} INFO - Starting attempt 1 of 1
[2024-03-25T16:26:56.741+0000] {taskinstance.py:2217} INFO - Executing <Task(GCSToBigQueryOperator): send_retail_to_dataset> on 2024-03-25 16:26:06.898165+00:00
[2024-03-25T16:26:56.754+0000] {standard_task_runner.py:60} INFO - Started process 1394 to run task
[2024-03-25T16:26:56.759+0000] {standard_task_runner.py:87} INFO - Running: ['***', 'tasks', 'run', 'retail_dag', 'send_retail_to_dataset', 'manual__2024-03-25T16:26:06.898165+00:00', '--job-id', '31', '--raw', '--subdir', 'DAGS_FOLDER/retail.py', '--cfg-path', '/tmp/tmpxr6uloix']
[2024-03-25T16:26:56.762+0000] {standard_task_runner.py:88} INFO - Job 31: Subtask send_retail_to_dataset
[2024-03-25T16:26:56.846+0000] {task_command.py:423} INFO - Running <TaskInstance: retail_dag.send_retail_to_dataset manual__2024-03-25T16:26:06.898165+00:00 [running]> on host b77f7ef9c21f
[2024-03-25T16:26:57.049+0000] {taskinstance.py:2513} INFO - Exporting env vars: AIRFLOW_CTX_DAG_OWNER='***' AIRFLOW_CTX_DAG_ID='retail_dag' AIRFLOW_CTX_TASK_ID='send_retail_to_dataset' AIRFLOW_CTX_EXECUTION_DATE='2024-03-25T16:26:06.898165+00:00' AIRFLOW_CTX_TRY_NUMBER='1' AIRFLOW_CTX_DAG_RUN_ID='manual__2024-03-25T16:26:06.898165+00:00'
[2024-03-25T16:26:57.071+0000] {connection.py:269} WARNING - Connection schemes (type: google_cloud_platform) shall not contain '_' according to RFC3986.
[2024-03-25T16:26:57.073+0000] {base.py:83} INFO - Using connection ID 'gcp' for task execution.
[2024-03-25T16:26:57.075+0000] {gcs_to_bigquery.py:379} INFO - Using existing BigQuery table for storing data...
[2024-03-25T16:26:57.167+0000] {gcs_to_bigquery.py:383} INFO - Executing: {'load': {'autodetect': True, 'createDisposition': 'CREATE_IF_NEEDED', 'destinationTable': {'projectId': '***-tutorial-418113', 'datasetId': '***-tutorial-418113', 'tableId': 'retail'}, 'sourceFormat': 'CSV', 'sourceUris': ['gs://marco_***_online_retail/raw/online_retail.csv'], 'writeDisposition': 'WRITE_TRUNCATE', 'ignoreUnknownValues': False, 'schema': {'fields': [{'name': 'InvoiceNo', 'type': 'STRING'}, {'name': 'StockCode', 'type': 'STRING'}, {'name': 'Description', 'type': 'TEXT', 'mode': 'NULLABLE'}, {'name': 'Quantity', 'type': 'INTEGER'}, {'name': 'InvoiceDate', 'type': 'DATETIME'}, {'name': 'UnitPrice', 'type': 'FLOAT'}, {'name': 'CustomerID', 'type': 'FLOAT', 'mode': 'NULLABLE'}, {'name': 'Country', 'type': 'STRING'}]}, 'skipLeadingRows': 1, 'fieldDelimiter': ',', 'quote': None, 'allowQuotedNewlines': 'true', 'encoding': 'UTF-8'}}
[2024-03-25T16:26:57.171+0000] {bigquery.py:1612} INFO - Inserting job ***_retail_dag_send_retail_to_dataset_2024_03_25T16_26_06_898165_00_00_5fb95aafac926c76f71fb1343999b90c
[2024-03-25T16:26:58.400+0000] {taskinstance.py:2731} ERROR - Task failed with exception
Traceback (most recent call last):
  File "/home/airflow/.local/lib/python3.8/site-packages/airflow/models/taskinstance.py", line 444, in _execute_task
    result = _execute_callable(context=context, **execute_callable_kwargs)
  File "/home/airflow/.local/lib/python3.8/site-packages/airflow/models/taskinstance.py", line 414, in _execute_callable
    return execute_callable(context=context, **execute_callable_kwargs)
  File "/home/airflow/.local/lib/python3.8/site-packages/airflow/providers/google/cloud/transfers/gcs_to_bigquery.py", line 384, in execute
    job: BigQueryJob | UnknownJob = self._submit_job(self.hook, job_id)
  File "/home/airflow/.local/lib/python3.8/site-packages/airflow/providers/google/cloud/transfers/gcs_to_bigquery.py", line 306, in _submit_job
    return hook.insert_job(
  File "/home/airflow/.local/lib/python3.8/site-packages/airflow/providers/google/common/hooks/base_google.py", line 485, in inner_wrapper
    return func(self, *args, **kwargs)
  File "/home/airflow/.local/lib/python3.8/site-packages/airflow/providers/google/cloud/hooks/bigquery.py", line 1615, in insert_job
    job_api_repr._begin()
  File "/home/airflow/.local/lib/python3.8/site-packages/google/cloud/bigquery/job/base.py", line 740, in _begin
    api_response = client._call_api(
  File "/home/airflow/.local/lib/python3.8/site-packages/google/cloud/bigquery/client.py", line 827, in _call_api
    return call()
  File "/home/airflow/.local/lib/python3.8/site-packages/google/api_core/retry/retry_unary.py", line 293, in retry_wrapped_func
    return retry_target(
  File "/home/airflow/.local/lib/python3.8/site-packages/google/api_core/retry/retry_unary.py", line 153, in retry_target
    _retry_error_helper(
  File "/home/airflow/.local/lib/python3.8/site-packages/google/api_core/retry/retry_base.py", line 212, in _retry_error_helper
    raise final_exc from source_exc
  File "/home/airflow/.local/lib/python3.8/site-packages/google/api_core/retry/retry_unary.py", line 144, in retry_target
    result = target()
  File "/home/airflow/.local/lib/python3.8/site-packages/google/cloud/_http/__init__.py", line 494, in api_request
    raise exceptions.from_http_response(response)
google.api_core.exceptions.BadRequest: 400 POST https://bigquery.googleapis.com/bigquery/v2/projects/airflow-tutorial-418113/jobs?prettyPrint=false: Invalid value for type: TEXT is not a valid value
[2024-03-25T16:26:58.426+0000] {taskinstance.py:1149} INFO - Marking task as FAILED. dag_id=retail_dag, task_id=send_retail_to_dataset, execution_date=20240325T162606, start_date=20240325T162656, end_date=20240325T162658
[2024-03-25T16:26:58.453+0000] {standard_task_runner.py:107} ERROR - Failed to execute job 31 for task send_retail_to_dataset (400 POST https://bigquery.googleapis.com/bigquery/v2/projects/airflow-tutorial-418113/jobs?prettyPrint=false: Invalid value for type: TEXT is not a valid value; 1394)
[2024-03-25T16:26:58.502+0000] {local_task_job_runner.py:234} INFO - Task exited with return code 1
[2024-03-25T16:26:58.539+0000] {taskinstance.py:3312} INFO - 0 downstream tasks scheduled from follow-on schedule check
