[2024-04-20T20:51:36.397+0000] {taskinstance.py:1979} INFO - Dependencies all met for dep_context=non-requeueable deps ti=<TaskInstance: dbt_dag_gcp.dbt_run manual__2024-04-20T20:51:34.297338+00:00 [queued]>
[2024-04-20T20:51:36.404+0000] {taskinstance.py:1979} INFO - Dependencies all met for dep_context=requeueable deps ti=<TaskInstance: dbt_dag_gcp.dbt_run manual__2024-04-20T20:51:34.297338+00:00 [queued]>
[2024-04-20T20:51:36.404+0000] {taskinstance.py:2193} INFO - Starting attempt 1 of 1
[2024-04-20T20:51:36.415+0000] {taskinstance.py:2217} INFO - Executing <Task(BashOperator): dbt_run> on 2024-04-20 20:51:34.297338+00:00
[2024-04-20T20:51:36.421+0000] {standard_task_runner.py:60} INFO - Started process 605 to run task
[2024-04-20T20:51:36.424+0000] {standard_task_runner.py:87} INFO - Running: ['***', 'tasks', 'run', 'dbt_dag_gcp', 'dbt_run', 'manual__2024-04-20T20:51:34.297338+00:00', '--job-id', '226', '--raw', '--subdir', 'DAGS_FOLDER/dbt_dag.py', '--cfg-path', '/tmp/tmpaq885m2m']
[2024-04-20T20:51:36.425+0000] {standard_task_runner.py:88} INFO - Job 226: Subtask dbt_run
[2024-04-20T20:51:36.464+0000] {task_command.py:423} INFO - Running <TaskInstance: dbt_dag_gcp.dbt_run manual__2024-04-20T20:51:34.297338+00:00 [running]> on host faf1dc8ef394
[2024-04-20T20:51:36.524+0000] {taskinstance.py:2513} INFO - Exporting env vars: AIRFLOW_CTX_DAG_OWNER='***' AIRFLOW_CTX_DAG_ID='dbt_dag_gcp' AIRFLOW_CTX_TASK_ID='dbt_run' AIRFLOW_CTX_EXECUTION_DATE='2024-04-20T20:51:34.297338+00:00' AIRFLOW_CTX_TRY_NUMBER='1' AIRFLOW_CTX_DAG_RUN_ID='manual__2024-04-20T20:51:34.297338+00:00'
[2024-04-20T20:51:36.525+0000] {subprocess.py:63} INFO - Tmp dir root location: /tmp
[2024-04-20T20:51:36.526+0000] {subprocess.py:75} INFO - Running command: ['/usr/bin/bash', '-c', 'cd /opt/***/dags/dbt/***_dbt_gcp && dbt run --profiles-dir .']
[2024-04-20T20:51:36.537+0000] {subprocess.py:86} INFO - Output:
[2024-04-20T20:51:36.539+0000] {subprocess.py:93} INFO - /usr/bin/bash: line 1: dbt: command not found
[2024-04-20T20:51:36.539+0000] {subprocess.py:97} INFO - Command exited with return code 127
[2024-04-20T20:51:36.549+0000] {taskinstance.py:2731} ERROR - Task failed with exception
Traceback (most recent call last):
  File "/home/airflow/.local/lib/python3.8/site-packages/airflow/models/taskinstance.py", line 444, in _execute_task
    result = _execute_callable(context=context, **execute_callable_kwargs)
  File "/home/airflow/.local/lib/python3.8/site-packages/airflow/models/taskinstance.py", line 414, in _execute_callable
    return execute_callable(context=context, **execute_callable_kwargs)
  File "/home/airflow/.local/lib/python3.8/site-packages/airflow/operators/bash.py", line 212, in execute
    raise AirflowException(
airflow.exceptions.AirflowException: Bash command failed. The command returned a non-zero exit code 127.
[2024-04-20T20:51:36.551+0000] {taskinstance.py:1149} INFO - Marking task as FAILED. dag_id=dbt_dag_gcp, task_id=dbt_run, execution_date=20240420T205134, start_date=20240420T205136, end_date=20240420T205136
[2024-04-20T20:51:36.562+0000] {standard_task_runner.py:107} ERROR - Failed to execute job 226 for task dbt_run (Bash command failed. The command returned a non-zero exit code 127.; 605)
[2024-04-20T20:51:36.597+0000] {local_task_job_runner.py:234} INFO - Task exited with return code 1
[2024-04-20T20:51:36.618+0000] {taskinstance.py:3312} INFO - 0 downstream tasks scheduled from follow-on schedule check
