[2024-03-25T16:09:49.264+0000] {taskinstance.py:1979} INFO - Dependencies all met for dep_context=non-requeueable deps ti=<TaskInstance: retail_dag.upload_csv_to_gcp manual__2024-03-25T16:09:37.749881+00:00 [queued]>
[2024-03-25T16:09:49.289+0000] {taskinstance.py:1979} INFO - Dependencies all met for dep_context=requeueable deps ti=<TaskInstance: retail_dag.upload_csv_to_gcp manual__2024-03-25T16:09:37.749881+00:00 [queued]>
[2024-03-25T16:09:49.291+0000] {taskinstance.py:2193} INFO - Starting attempt 1 of 1
[2024-03-25T16:09:49.328+0000] {taskinstance.py:2217} INFO - Executing <Task(LocalFilesystemToGCSOperator): upload_csv_to_gcp> on 2024-03-25 16:09:37.749881+00:00
[2024-03-25T16:09:49.351+0000] {standard_task_runner.py:60} INFO - Started process 1090 to run task
[2024-03-25T16:09:49.378+0000] {standard_task_runner.py:87} INFO - Running: ['***', 'tasks', 'run', 'retail_dag', 'upload_csv_to_gcp', 'manual__2024-03-25T16:09:37.749881+00:00', '--job-id', '21', '--raw', '--subdir', 'DAGS_FOLDER/retail.py', '--cfg-path', '/tmp/tmpn049ixjn']
[2024-03-25T16:09:49.397+0000] {standard_task_runner.py:88} INFO - Job 21: Subtask upload_csv_to_gcp
[2024-03-25T16:09:49.619+0000] {task_command.py:423} INFO - Running <TaskInstance: retail_dag.upload_csv_to_gcp manual__2024-03-25T16:09:37.749881+00:00 [running]> on host b77f7ef9c21f
[2024-03-25T16:09:49.908+0000] {taskinstance.py:2513} INFO - Exporting env vars: AIRFLOW_CTX_DAG_OWNER='***' AIRFLOW_CTX_DAG_ID='retail_dag' AIRFLOW_CTX_TASK_ID='upload_csv_to_gcp' AIRFLOW_CTX_EXECUTION_DATE='2024-03-25T16:09:37.749881+00:00' AIRFLOW_CTX_TRY_NUMBER='1' AIRFLOW_CTX_DAG_RUN_ID='manual__2024-03-25T16:09:37.749881+00:00'
[2024-03-25T16:09:49.931+0000] {connection.py:269} WARNING - Connection schemes (type: google_cloud_platform) shall not contain '_' according to RFC3986.
[2024-03-25T16:09:49.933+0000] {base.py:83} INFO - Using connection ID 'gcp' for task execution.
[2024-03-25T16:10:09.653+0000] {local_task_job_runner.py:302} WARNING - State of this instance has been externally set to restarting. Terminating instance.
[2024-03-25T16:10:09.665+0000] {process_utils.py:131} INFO - Sending 15 to group 1090. PIDs of all processes in the group: [1090]
[2024-03-25T16:10:09.665+0000] {process_utils.py:86} INFO - Sending the signal 15 to group 1090
[2024-03-25T16:10:09.667+0000] {taskinstance.py:2483} ERROR - Received SIGTERM. Terminating subprocesses.
[2024-03-25T16:10:09.699+0000] {taskinstance.py:2731} ERROR - Task failed with exception
Traceback (most recent call last):
  File "/home/airflow/.local/lib/python3.8/site-packages/airflow/models/taskinstance.py", line 444, in _execute_task
    result = _execute_callable(context=context, **execute_callable_kwargs)
  File "/home/airflow/.local/lib/python3.8/site-packages/airflow/models/taskinstance.py", line 414, in _execute_callable
    return execute_callable(context=context, **execute_callable_kwargs)
  File "/home/airflow/.local/lib/python3.8/site-packages/airflow/providers/google/cloud/transfers/local_to_gcs.py", line 110, in execute
    hook.upload(
  File "/home/airflow/.local/lib/python3.8/site-packages/airflow/providers/google/cloud/hooks/gcs.py", line 551, in upload
    _call_with_retry(
  File "/home/airflow/.local/lib/python3.8/site-packages/airflow/providers/google/cloud/hooks/gcs.py", line 509, in _call_with_retry
    f()
  File "/home/airflow/.local/lib/python3.8/site-packages/google/cloud/storage/blob.py", line 2929, in upload_from_filename
    self._handle_filename_and_upload(
  File "/home/airflow/.local/lib/python3.8/site-packages/google/cloud/storage/blob.py", line 2799, in _handle_filename_and_upload
    self._prep_and_do_upload(
  File "/home/airflow/.local/lib/python3.8/site-packages/google/cloud/storage/blob.py", line 2607, in _prep_and_do_upload
    created_json = self._do_upload(
  File "/home/airflow/.local/lib/python3.8/site-packages/google/cloud/storage/blob.py", line 2430, in _do_upload
    response = self._do_resumable_upload(
  File "/home/airflow/.local/lib/python3.8/site-packages/google/cloud/storage/blob.py", line 2266, in _do_resumable_upload
    response = upload.transmit_next_chunk(transport, timeout=timeout)
  File "/home/airflow/.local/lib/python3.8/site-packages/google/resumable_media/requests/upload.py", line 515, in transmit_next_chunk
    return _request_helpers.wait_and_retry(
  File "/home/airflow/.local/lib/python3.8/site-packages/google/resumable_media/requests/_request_helpers.py", line 155, in wait_and_retry
    response = func()
  File "/home/airflow/.local/lib/python3.8/site-packages/google/resumable_media/requests/upload.py", line 507, in retriable_request
    result = transport.request(
  File "/home/airflow/.local/lib/python3.8/site-packages/google/auth/transport/requests.py", line 541, in request
    response = super(AuthorizedSession, self).request(
  File "/home/airflow/.local/lib/python3.8/site-packages/requests/sessions.py", line 589, in request
    resp = self.send(prep, **send_kwargs)
  File "/home/airflow/.local/lib/python3.8/site-packages/requests/sessions.py", line 703, in send
    r = adapter.send(request, **kwargs)
  File "/home/airflow/.local/lib/python3.8/site-packages/requests/adapters.py", line 486, in send
    resp = conn.urlopen(
  File "/home/airflow/.local/lib/python3.8/site-packages/urllib3/connectionpool.py", line 715, in urlopen
    httplib_response = self._make_request(
  File "/home/airflow/.local/lib/python3.8/site-packages/urllib3/connectionpool.py", line 416, in _make_request
    conn.request(method, url, **httplib_request_kw)
  File "/home/airflow/.local/lib/python3.8/site-packages/urllib3/connection.py", line 244, in request
    super(HTTPConnection, self).request(method, url, body=body, headers=headers)
  File "/usr/local/lib/python3.8/http/client.py", line 1256, in request
    self._send_request(method, url, body, headers, encode_chunked)
  File "/usr/local/lib/python3.8/http/client.py", line 1302, in _send_request
    self.endheaders(body, encode_chunked=encode_chunked)
  File "/usr/local/lib/python3.8/http/client.py", line 1251, in endheaders
    self._send_output(message_body, encode_chunked=encode_chunked)
  File "/usr/local/lib/python3.8/http/client.py", line 1050, in _send_output
    self.send(chunk)
  File "/usr/local/lib/python3.8/http/client.py", line 972, in send
    self.sock.sendall(data)
  File "/usr/local/lib/python3.8/ssl.py", line 1237, in sendall
    v = self.send(byte_view[count:])
  File "/usr/local/lib/python3.8/ssl.py", line 1206, in send
    return self._sslobj.write(data)
  File "/home/airflow/.local/lib/python3.8/site-packages/airflow/models/taskinstance.py", line 2485, in signal_handler
    raise AirflowException("Task received SIGTERM signal")
airflow.exceptions.AirflowException: Task received SIGTERM signal
[2024-03-25T16:10:09.745+0000] {taskinstance.py:1149} INFO - Marking task as UP_FOR_RETRY. dag_id=retail_dag, task_id=upload_csv_to_gcp, execution_date=20240325T160937, start_date=20240325T160949, end_date=20240325T161009
[2024-03-25T16:10:09.778+0000] {standard_task_runner.py:107} ERROR - Failed to execute job 21 for task upload_csv_to_gcp (Task received SIGTERM signal; 1090)
[2024-03-25T16:10:09.840+0000] {process_utils.py:79} INFO - Process psutil.Process(pid=1090, status='terminated', exitcode=1, started='16:09:48') (1090) terminated with exit code 1
