[2024-04-20T20:46:29.320+0000] {taskinstance.py:1979} INFO - Dependencies all met for dep_context=non-requeueable deps ti=<TaskInstance: dbt_dag_gcp.dbt_run manual__2024-04-20T20:46:27.397605+00:00 [queued]>
[2024-04-20T20:46:29.331+0000] {taskinstance.py:1979} INFO - Dependencies all met for dep_context=requeueable deps ti=<TaskInstance: dbt_dag_gcp.dbt_run manual__2024-04-20T20:46:27.397605+00:00 [queued]>
[2024-04-20T20:46:29.332+0000] {taskinstance.py:2193} INFO - Starting attempt 1 of 1
[2024-04-20T20:46:29.346+0000] {taskinstance.py:2217} INFO - Executing <Task(BashOperator): dbt_run> on 2024-04-20 20:46:27.397605+00:00
[2024-04-20T20:46:29.353+0000] {standard_task_runner.py:60} INFO - Started process 512 to run task
[2024-04-20T20:46:29.355+0000] {standard_task_runner.py:87} INFO - Running: ['***', 'tasks', 'run', 'dbt_dag_gcp', 'dbt_run', 'manual__2024-04-20T20:46:27.397605+00:00', '--job-id', '224', '--raw', '--subdir', 'DAGS_FOLDER/dbt_dag.py', '--cfg-path', '/tmp/tmp08udzmq3']
[2024-04-20T20:46:29.356+0000] {standard_task_runner.py:88} INFO - Job 224: Subtask dbt_run
[2024-04-20T20:46:29.394+0000] {task_command.py:423} INFO - Running <TaskInstance: dbt_dag_gcp.dbt_run manual__2024-04-20T20:46:27.397605+00:00 [running]> on host faf1dc8ef394
[2024-04-20T20:46:29.457+0000] {taskinstance.py:2513} INFO - Exporting env vars: AIRFLOW_CTX_DAG_OWNER='***' AIRFLOW_CTX_DAG_ID='dbt_dag_gcp' AIRFLOW_CTX_TASK_ID='dbt_run' AIRFLOW_CTX_EXECUTION_DATE='2024-04-20T20:46:27.397605+00:00' AIRFLOW_CTX_TRY_NUMBER='1' AIRFLOW_CTX_DAG_RUN_ID='manual__2024-04-20T20:46:27.397605+00:00'
[2024-04-20T20:46:29.458+0000] {subprocess.py:63} INFO - Tmp dir root location: /tmp
[2024-04-20T20:46:29.459+0000] {subprocess.py:75} INFO - Running command: ['/usr/bin/bash', '-c', 'cd ../..//opt/***/dags/dbt/***_dbt_gcp && dbt run --profiles-dir .']
[2024-04-20T20:46:29.471+0000] {subprocess.py:86} INFO - Output:
[2024-04-20T20:46:29.476+0000] {subprocess.py:93} INFO - /usr/bin/bash: line 1: dbt: command not found
[2024-04-20T20:46:29.477+0000] {subprocess.py:97} INFO - Command exited with return code 127
[2024-04-20T20:46:29.486+0000] {taskinstance.py:2731} ERROR - Task failed with exception
Traceback (most recent call last):
  File "/home/airflow/.local/lib/python3.8/site-packages/airflow/models/taskinstance.py", line 444, in _execute_task
    result = _execute_callable(context=context, **execute_callable_kwargs)
  File "/home/airflow/.local/lib/python3.8/site-packages/airflow/models/taskinstance.py", line 414, in _execute_callable
    return execute_callable(context=context, **execute_callable_kwargs)
  File "/home/airflow/.local/lib/python3.8/site-packages/airflow/operators/bash.py", line 212, in execute
    raise AirflowException(
airflow.exceptions.AirflowException: Bash command failed. The command returned a non-zero exit code 127.
[2024-04-20T20:46:29.489+0000] {taskinstance.py:1149} INFO - Marking task as FAILED. dag_id=dbt_dag_gcp, task_id=dbt_run, execution_date=20240420T204627, start_date=20240420T204629, end_date=20240420T204629
[2024-04-20T20:46:29.499+0000] {standard_task_runner.py:107} ERROR - Failed to execute job 224 for task dbt_run (Bash command failed. The command returned a non-zero exit code 127.; 512)
[2024-04-20T20:46:29.527+0000] {local_task_job_runner.py:234} INFO - Task exited with return code 1
[2024-04-20T20:46:29.548+0000] {taskinstance.py:3312} INFO - 0 downstream tasks scheduled from follow-on schedule check
