[2024-04-20T21:10:12.970+0000] {taskinstance.py:1979} INFO - Dependencies all met for dep_context=non-requeueable deps ti=<TaskInstance: dbt_dag_gcp.dbt_run manual__2024-04-20T21:10:06.537984+00:00 [queued]>
[2024-04-20T21:10:12.991+0000] {taskinstance.py:1979} INFO - Dependencies all met for dep_context=requeueable deps ti=<TaskInstance: dbt_dag_gcp.dbt_run manual__2024-04-20T21:10:06.537984+00:00 [queued]>
[2024-04-20T21:10:12.992+0000] {taskinstance.py:2193} INFO - Starting attempt 1 of 1
[2024-04-20T21:10:13.025+0000] {taskinstance.py:2217} INFO - Executing <Task(BashOperator): dbt_run> on 2024-04-20 21:10:06.537984+00:00
[2024-04-20T21:10:13.035+0000] {standard_task_runner.py:60} INFO - Started process 91 to run task
[2024-04-20T21:10:13.041+0000] {standard_task_runner.py:87} INFO - Running: ['***', 'tasks', 'run', 'dbt_dag_gcp', 'dbt_run', 'manual__2024-04-20T21:10:06.537984+00:00', '--job-id', '238', '--raw', '--subdir', 'DAGS_FOLDER/dbt_dag.py', '--cfg-path', '/tmp/tmpacsmsn1y']
[2024-04-20T21:10:13.045+0000] {standard_task_runner.py:88} INFO - Job 238: Subtask dbt_run
[2024-04-20T21:10:13.166+0000] {task_command.py:423} INFO - Running <TaskInstance: dbt_dag_gcp.dbt_run manual__2024-04-20T21:10:06.537984+00:00 [running]> on host cead0b1f6896
[2024-04-20T21:10:13.353+0000] {taskinstance.py:2513} INFO - Exporting env vars: AIRFLOW_CTX_DAG_OWNER='***' AIRFLOW_CTX_DAG_ID='dbt_dag_gcp' AIRFLOW_CTX_TASK_ID='dbt_run' AIRFLOW_CTX_EXECUTION_DATE='2024-04-20T21:10:06.537984+00:00' AIRFLOW_CTX_TRY_NUMBER='1' AIRFLOW_CTX_DAG_RUN_ID='manual__2024-04-20T21:10:06.537984+00:00'
[2024-04-20T21:10:13.357+0000] {subprocess.py:63} INFO - Tmp dir root location: /tmp
[2024-04-20T21:10:13.358+0000] {subprocess.py:75} INFO - Running command: ['/usr/bin/bash', '-c', 'cd /opt/***/dags/dbt/***_dbt_gcp && dbt run --profiles-dir .']
[2024-04-20T21:10:13.393+0000] {subprocess.py:86} INFO - Output:
[2024-04-20T21:10:23.623+0000] {subprocess.py:93} INFO - [0m21:10:23  Running with dbt=1.7.10
[2024-04-20T21:10:30.571+0000] {subprocess.py:93} INFO - [0m21:10:30  Registered adapter: bigquery=1.7.6
[2024-04-20T21:10:30.644+0000] {subprocess.py:93} INFO - [0m21:10:30  Unable to do partial parsing because profile has changed
[2024-04-20T21:10:35.655+0000] {subprocess.py:93} INFO - [0m21:10:35  Found 5 models, 10 tests, 1 source, 0 exposures, 0 metrics, 454 macros, 0 groups, 0 semantic models
[2024-04-20T21:10:35.665+0000] {subprocess.py:93} INFO - [0m21:10:35
[2024-04-20T21:10:35.698+0000] {subprocess.py:93} INFO - [0m21:10:35
[2024-04-20T21:10:35.701+0000] {subprocess.py:93} INFO - [0m21:10:35  Finished running  in 0 hours 0 minutes and 0.03 seconds (0.03s).
[2024-04-20T21:10:35.703+0000] {subprocess.py:93} INFO - [0m21:10:35  Encountered an error:
[2024-04-20T21:10:35.703+0000] {subprocess.py:93} INFO - Database Error
[2024-04-20T21:10:35.703+0000] {subprocess.py:93} INFO -   [Errno 2] No such file or directory: '/root/project/***-project/include/gcp/service_account.json'
[2024-04-20T21:10:37.989+0000] {subprocess.py:97} INFO - Command exited with return code 2
[2024-04-20T21:10:38.015+0000] {taskinstance.py:2731} ERROR - Task failed with exception
Traceback (most recent call last):
  File "/home/airflow/.local/lib/python3.8/site-packages/airflow/models/taskinstance.py", line 444, in _execute_task
    result = _execute_callable(context=context, **execute_callable_kwargs)
  File "/home/airflow/.local/lib/python3.8/site-packages/airflow/models/taskinstance.py", line 414, in _execute_callable
    return execute_callable(context=context, **execute_callable_kwargs)
  File "/home/airflow/.local/lib/python3.8/site-packages/airflow/operators/bash.py", line 212, in execute
    raise AirflowException(
airflow.exceptions.AirflowException: Bash command failed. The command returned a non-zero exit code 2.
[2024-04-20T21:10:38.024+0000] {taskinstance.py:1149} INFO - Marking task as FAILED. dag_id=dbt_dag_gcp, task_id=dbt_run, execution_date=20240420T211006, start_date=20240420T211012, end_date=20240420T211038
[2024-04-20T21:10:38.060+0000] {standard_task_runner.py:107} ERROR - Failed to execute job 238 for task dbt_run (Bash command failed. The command returned a non-zero exit code 2.; 91)
[2024-04-20T21:10:38.116+0000] {local_task_job_runner.py:234} INFO - Task exited with return code 1
[2024-04-20T21:10:38.172+0000] {taskinstance.py:3312} INFO - 0 downstream tasks scheduled from follow-on schedule check
