[2024-04-20T19:41:19.059+0000] {taskinstance.py:1979} INFO - Dependencies all met for dep_context=non-requeueable deps ti=<TaskInstance: dbt_dag_gcp.dbt_run scheduled__2024-02-24T00:00:00+00:00 [queued]>
[2024-04-20T19:41:19.077+0000] {taskinstance.py:1979} INFO - Dependencies all met for dep_context=requeueable deps ti=<TaskInstance: dbt_dag_gcp.dbt_run scheduled__2024-02-24T00:00:00+00:00 [queued]>
[2024-04-20T19:41:19.078+0000] {taskinstance.py:2193} INFO - Starting attempt 1 of 1
[2024-04-20T19:41:19.176+0000] {taskinstance.py:2217} INFO - Executing <Task(BashOperator): dbt_run> on 2024-02-24 00:00:00+00:00
[2024-04-20T19:41:19.186+0000] {standard_task_runner.py:60} INFO - Started process 280 to run task
[2024-04-20T19:41:19.191+0000] {standard_task_runner.py:87} INFO - Running: ['***', 'tasks', 'run', 'dbt_dag_gcp', 'dbt_run', 'scheduled__2024-02-24T00:00:00+00:00', '--job-id', '138', '--raw', '--subdir', 'DAGS_FOLDER/dbt_dag.py', '--cfg-path', '/tmp/tmpritgkvo9']
[2024-04-20T19:41:19.195+0000] {standard_task_runner.py:88} INFO - Job 138: Subtask dbt_run
[2024-04-20T19:41:19.289+0000] {task_command.py:423} INFO - Running <TaskInstance: dbt_dag_gcp.dbt_run scheduled__2024-02-24T00:00:00+00:00 [running]> on host 8141e76a239d
[2024-04-20T19:41:19.438+0000] {taskinstance.py:2513} INFO - Exporting env vars: AIRFLOW_CTX_DAG_OWNER='***' AIRFLOW_CTX_DAG_ID='dbt_dag_gcp' AIRFLOW_CTX_TASK_ID='dbt_run' AIRFLOW_CTX_EXECUTION_DATE='2024-02-24T00:00:00+00:00' AIRFLOW_CTX_TRY_NUMBER='1' AIRFLOW_CTX_DAG_RUN_ID='scheduled__2024-02-24T00:00:00+00:00'
[2024-04-20T19:41:19.441+0000] {subprocess.py:63} INFO - Tmp dir root location: /tmp
[2024-04-20T19:41:19.442+0000] {subprocess.py:75} INFO - Running command: ['/usr/bin/bash', '-c', 'cd /opt/***dags/dbt/***_dbt_gcp && dbt run . --profiles_dir .']
[2024-04-20T19:41:19.462+0000] {subprocess.py:86} INFO - Output:
[2024-04-20T19:41:19.466+0000] {subprocess.py:93} INFO - /usr/bin/bash: line 1: cd: /opt/***dags/dbt/***_dbt_gcp: No such file or directory
[2024-04-20T19:41:19.467+0000] {subprocess.py:97} INFO - Command exited with return code 1
[2024-04-20T19:41:19.488+0000] {taskinstance.py:2731} ERROR - Task failed with exception
Traceback (most recent call last):
  File "/home/airflow/.local/lib/python3.8/site-packages/airflow/models/taskinstance.py", line 444, in _execute_task
    result = _execute_callable(context=context, **execute_callable_kwargs)
  File "/home/airflow/.local/lib/python3.8/site-packages/airflow/models/taskinstance.py", line 414, in _execute_callable
    return execute_callable(context=context, **execute_callable_kwargs)
  File "/home/airflow/.local/lib/python3.8/site-packages/airflow/operators/bash.py", line 212, in execute
    raise AirflowException(
airflow.exceptions.AirflowException: Bash command failed. The command returned a non-zero exit code 1.
[2024-04-20T19:41:19.494+0000] {taskinstance.py:1149} INFO - Marking task as FAILED. dag_id=dbt_dag_gcp, task_id=dbt_run, execution_date=20240224T000000, start_date=20240420T194119, end_date=20240420T194119
[2024-04-20T19:41:19.520+0000] {standard_task_runner.py:107} ERROR - Failed to execute job 138 for task dbt_run (Bash command failed. The command returned a non-zero exit code 1.; 280)
[2024-04-20T19:41:19.566+0000] {local_task_job_runner.py:234} INFO - Task exited with return code 1
[2024-04-20T19:41:19.619+0000] {taskinstance.py:3312} INFO - 0 downstream tasks scheduled from follow-on schedule check
